Workbook

Sheet 구매리스트
A2: 말소증 | F2: 차량등록증
A3: ID | B3: 850942 | C3: 등록번호 | F3: 등록번호 | H3: 등록증날짜 | I3: 45875
A4: 차량번호 | B4: 19더9065 | C4: 영문차량번호 | D4: 19DEO9065 | F4: 형식 | G4: JC51 | H4: 원동기 | I4: B47D20A
A5: 차명 | B5: BMW 520d xDrive | C5: 차대번호 | D5: WBAJC5105HG850942 | F5: 제원 | G5: 001-2-00057-0002-1217 | H5: 연도 | I5: 2017-02
A6: 최초등록일 | B6: 42853 | C6: 연도 | D6: 2017 | F6: 차종 | G6: 중형승용 | H6: 차종 | I6: =SUBSTITUTE(SUBSTITUTE(SUBSTITUTE(SUBSTITUTE(SUBSTITUTE(SUBSTITUTE(G6,"승용 소형","Small Passenger"),"승용 중형","Medium Passenger"),"승용 대형","HEAVY Passenger"),"중형 승합","Medium Ven"),"대형 승합","Large Ven"),"중형 화물","Medium Cargo") -> 0
A7: 말소등록일 | B7: 45898 | C7: 주행거리 | D7: 167725 | F7: 길이 | G7: 4935 | H7: 너비 | I7: 1860
F8: 높이 | G8: 1455 | H8: 총중량 | I8: 2095
A9: VSL | F9: 인원 | G9: 5 | H9: 최대적재량
A10: Port | B10: INCHOEN, KOREA | C10: 목적국 | D10: DURRESS, ALBANIA | F10: 배기량 | G10: 1995 | H10: 검사시작 | I10: 45775
A11: VSL | B11: MV HAE SHIN V.2509 | C11: 선적일 | F11: 출력 | G11: 190/4000 | H11: 종료 | I11: 46504
A12: 컨테이너 NO | B12: RORO 2-6_3 | C12: con/roro | D12: RORO | F12: 기통 | G12: 4 | H12: 주행거리 | I12: 163268
A13: 컨사이니 | F13: 연료 | G13: 경유 | I13: =SUBSTITUTE(SUBSTITUTE(SUBSTITUTE(SUBSTITUTE(G13,"휘발유","GASOLINE"),"경유","DIESEL"),"LPG","LPG"),"하이브리드","HYBRID") -> 0
A14: 컨사이니 | B14: VIA AUTO 811881897 MAGJISTRALJA FERIZAJ PRISHTINEPN,PRELEZ I JERLIVE, 70000, FERIZAJ, KOSOVO EMAIL: INFO@VIA AUTO-KS.COM +38348507024 | C14: NAME | D14: =B14 -> 0
A15: 판매금 | B15: 14730 | C15: 운임 | D15: 1670 | I15: {=_xlfn.TEXTJOIN(",",, _xlfn.UNIQUE(_xlfn.IFNA(INDEX({"GASOLIN","DIESEL","LPG"}, MATCH(G15,{"휘발유","경유","LPG"},0)),""),1))}
C16: 합계 | D16: =SUM(B15,D15) -> 0
B23: INCHOEN, KOREA | D23: DURRESS, ALBANIA
B24: MASAN, KOREA | D24: AZERBAIJAN
B25: PYEONGTAEK, KOREA | D25: FRANCE
B26: BUSAN, KOREA | D26: CHILE
D27: JEBEL ALI, U.A.E(DUBAI)
D28: SYRIA
D29: GERMANY , HAMBURG
D30: SAUDI ARABIA , DAMMAM
D31: Netherlands , Rotterdam
D32: SWEDEN , GOTHENBURG
D33: KOPER , MOLDOVA
D34: MOLDOVA
D35: BURGAS, BULGARIA
D36: NORRKOPING
D37: KYRGYZSTAN
D38: KAZAKHSTAN
D39: VLADIVOSTOK, RUSSIA
D40: 123456

Sheet 한글등록증
A1: ■자동차등록규칙 [별지 제1호 서식] <개정 2017. 10. 26> 수출 통관용 | Q1: (앞 쪽)
A2: 자 동 차 등 록 증
B3: 제 | C3: =구매리스트!G3 -> 0 | H3: 호 | M3: 최초등록일 : | O3: =구매리스트!B6 -> 0
A4: ① 자동차등록번호 | E4: =구매리스트!B4 -> 0 | J4: ② 차 종 | M4: =구매리스트!G6 -> 0 | O4: ③용도 | P4: 자가용
A5: ④ 차 명 | E5: =구매리스트!B5 -> 0 | J5: ⑤ 형식 및 모델연도 | M5: =구매리스트!G4 -> 0 | P5: =구매리스트!I5 -> 0
A6: ⑥ 차 대 번 호 | E6: =구매리스트!D5 -> 0 | J6: ⑦ 원 동 기 형 식 | M6: =구매리스트!I4 -> 0
A7: ⑧ 사 용 본 거 지 | E7: 경기도 시흥시 산기대학로 163, A동 328호(정왕동)
A8: 소유자 | C8: ⑨성명(명칭) | E8: 주식회사 싼카 (상품용) | J8: 생 년 월 일 (법 인 등 록 번호) | M8: 120111-0922270
A10: 「자동차관리법」제8조에 따라 위와 같이 등록하였음을 증명합니다.
B11: ※ 유의사항 : 전기자동차 또는 수소전기자동차인 경우 ⑦번란의 '원동기형식'은 '구동전동기형식'을 말합니다.
L13: =구매리스트!I3 -> 0
J15: 대 한 민 국
A18: 1.제 원 | L18: 4. 검사유효기간
A19: ⑪ | B19: 제원관리번호 | F19: =구매리스트!G5 -> 0 | L19: 연월일 | M19: 연월일 | N19: 검 사 | O19: 주 행 | P19: 검사책 | Q19: 검 사
B20: (형식승인번호) | L20: 부 터 | M20: 까 지 | N20: 시행장소 | O20: 거 리 | P20: 임자확인 | Q20: 구 분
A21: ⑫ | B21: 길 이 | D21: =구매리스트!G7 -> 0 | F21: mm | G21: ⑬ | H21: 너 비 | I21: =구매리스트!I7 -> 0 | J21: mm | L21: =구매리스트!I10 -> 0 | M21: =구매리스트!I11 -> 0 | O21: =구매리스트!I12 -> 0
A22: ⑭ | B22: 높 이 | D22: =구매리스트!G8 -> 0 | F22: mm | G22: ⑮ | H22: 총 중 량 | I22: =구매리스트!I8 -> 0 | J22: kg
A23: ⑯ | B23: 승차정원 | D23: =구매리스트!G9 -> 0 | F23: 명 | G23: ⑰ | H23: 최대적재량 | I23: =구매리스트!I9 -> 0 | J23: kg
A24: ⑱ | B24: 배기량 또는 | D24: =구매리스트!G10 -> 0 | I24: cc,(Ah ,[Ah]
B25: 구동축전지 용량
A27: ⑲ | B27: 정격출력 | D27: =구매리스트!G11 -> 0 | H27: Ps/rpm,(kW/rpm),[kW/rpm]
A28: ⑳ | B28: 기통수 | D28: =구매리스트!G12 -> 0 | I28: 기통,(V),[kW]
A29: (구동축전지정격전압)
A30: [연료전지 최고출력]
A31: ㉑ | B31: 연료의종류 및 연료소비율 | D31: =구매리스트!G13 -> 0 | F31: =구매리스트!H13 -> 0 | H31: km/l,(km/kWh),[km/kg]
A32: ㉒ | B32: 구동축전지 셀의제조사 | G32: ㉓ | H32: 구동축전지 셀의형태
A33: ㉔ | B33: 구동축전지셀의주요원료
A34: 유의사항 : ⑱~㉑에서 기재 단위는 사용연료의 종류가 전기인 자동차의 경우는 (),수소전기자동차의 경우는[]을 말합니다.「자동차관리법 시행규칙」별표1 제2회의 특수자동차의 경우 최대적재량은 피견인자동차를 연결하기위해 허용되는 최대수직하중을 말하며 견인능력과는무관합니다,㉒~㉔는 구동축전지를 갖춘 자동차(외부 전기공급원을 통해 충전할 수 없는 구조인 자동차는제외)의경우만 해당합니다.
A38: 2.등록번호판 교부 및 봉인 | L38: ※ 주의사항 : ㉚ 항 첫째란에는 신규등록일을 적습니다.
A39: ㉕ 구분 | D39: ㉖ 번호판발급일 | H39: ㉗ 발급대행자확인 | L39: 비고
A42: 3. 저당권등록사실(저당권등록의 내용은 자동차등록원부(을)를 열람,확인하시기 바랍니다)
A43: ㉘ 구분(설정 또는 말소) | H43: ㉙ 날 짜
G47: ※ 뒷면의 '유의사항'을 꼭 읽어보시기 바랍니다. | N47: 210㎜ x 297㎜[백상지 또는 중질지 80g/㎡]

Sheet 영문등록증
A1: ■Motor Vehicle Registration Rules [Attachment No. 1 Form] <Revised 2017. 10. 26> For export customs clearance | Q1: (front page)
A2: Certificate of Registration of Automobile
B3: No | C3: =구매리스트!G3 -> 0 | J3: First Registration Date : | O3: =구매리스트!B6 -> 0
A4: ① Registration No. | E4: =구매리스트!D4 -> 0 | J4: ② car type | M4: =구매리스트!I6 -> 0 | O4: ③Usage | P4: Private car
A5: ④ Car Name | E5: =구매리스트!B5 -> 0 | J5: ⑤ Model &Year | M5: =구매리스트!G4 -> 0 | P5: =구매리스트!I5 -> 0
A6: ⑥ Vehicle ID No. | E6: =구매리스트!D5 -> 0 | J6: ⑦ Motor Type | M6: =구매리스트!I4 -> 0
A7: ⑧ Usage Basc | E7: 163 Sangidaehak-ro, Siheung-si, Gyeonggi-do, Korea
A8: Owner | C8: ⑨ Address | E8: SSANCAR LTD,. | J8: ID Card No. | M8: 120111-0922270
A10: 「It is proved that it was registered as above in accordance with Article 8 of the Motor Vehicle Management Act.
B11: ※ Note: In the case of an electric vehicle or hydrogen fuel cell vehicle, the 'prime motor type' in column ⑦ refers to the 'drive motor type
L13: =구매리스트!I3 -> 0
J15: Republic of Korea
A18: 1.Specifications | L18: 4. Validity period of inspection
A19: ⑪ | B19: Specification Control Number | F19: =구매리스트!G5 -> 0 | L19: Date Boot | M19: Date Until | N19: Place of Inspection | O19: mileage | P19: Inspect manager check | Q19: Prosecutor Division
B20: (Type approval number)
A21: ⑫ | B21: Length | D21: =구매리스트!G7 -> 0 | F21: mm | G21: ⑬ | H21: Width | I21: =구매리스트!I7 -> 0 | J21: mm | L21: =구매리스트!I10 -> 0 | M21: =구매리스트!I11 -> 0 | O21: =구매리스트!I12 -> 0
A22: ⑭ | B22: Height | D22: =구매리스트!G8 -> 0 | F22: mm | G22: ⑮ | H22: Weight | I22: =구매리스트!I8 -> 0 | J22: kg
A23: ⑯ | B23: Passenger Capacity | D23: =구매리스트!G9 -> 0 | F23: Person | G23: ⑰ | H23: Maximum load | I23: =구매리스트!I9 -> 0 | J23: kg
A24: ⑱ | B24: Displacement or | D24: =구매리스트!G10 -> 0 | I24: cc,(Ah ,[Ah]
B25: Drive battery capacity
A27: ⑲ | B27: Rated Output | D27: =구매리스트!G11 -> 0 | H27: Ps/rpm,(kW/rpm),[kW/rpm]
A28: ⑳ | B28: Number of Cylinders | D28: =구매리스트!G12 -> 0 | I28: Cylinders, (V),[kW]
A29: (Drive Storage Voltage)
A30: [Maximum Fuel Cell Output]
A31: ㉑ | B31: Type of fuel and fuel consumption rate | D31: =구매리스트!I13 -> 0 | F31: =구매리스트!H13 -> 0 | H31: km/l,(km/kWh),[km/kg]
A32: ㉒ | B32: Manufacturer of drive battery cells | G32: ㉓ | H32: Shape of drive battery cell
A33: ㉔ | B33: Main raw materials of drive storage battery cells
A34: Note: In (18)~(21), the unit used refers to () in the case of an electric vehicle and [] in the case of a hydrogen fuel electric vehicle. In the case of special vehicles in Schedule 1 2 of the Enforcement Regulations of the Motor Vehicle Management Act, the maximum load refers to the maximum vertical load allowed to connect the towed vehicle and is not related to the towing capacity, (22)~(24) applies only to vehicles equipped with drive storage batteries (excluding vehicles with structures that cannot be charged through an external electricity source).
A38: 2.Registration plate issued and sealed | L38: ※ Note: In the first column of paragraph ㉚, write the date of new registration.
A39: ㉕ Classification | D39: ㉖ License plate issuance date | H39: ㉗ Confirmation of issuing agent | L39: REMARKS
A42: 3. Fact of mortgage registration (The contents of the mortgage registration are in the motor vehicle registration ledgerPlease perusal and confirm)
A43: ㉘ Classification (setting or erasure) | H43: ㉙ Date
G47: ※ Please read the 'Notes' on the back. | N47: 210mm x 297mm [white or heavy paper 80g/㎡]

Sheet 말소증
A1: ■ 자동차등록규칙 [별지 제 20호 서식] <개정 2025. 1. 10.>
A2: ■ 자동차등록규칙 [별지 제 20호 서식] <개정 2025. 1. 10.>
A3: Motor vehicle Registration Rules [Annex Form 20]
A4: 자동차말소등록사실증명서
A5: Certificate of De-registration of Motor Vehicle
A6: 제 | B6: =구매리스트!D3 -> 0 | F6: 호 (No. )
A8: 자동차의 표 시 Vehicle Details | C8: 자동차등록번호 | E8: =구매리스트!B4 -> 0 | H8: 차종 및 주행거리 | K8: 승용
C9: Registration No. | E9: =구매리스트!D4 -> 0 | H9: Vehicle Type and Mileage | K9: =구매리스트!D7 -> 0
C10: 차명 | E10: =구매리스트!B5 -> 0 | H10: 차대번호 | K10: =구매리스트!D5 -> 0
C11: Model | H11: Chassis No.
C12: 원동기형식 | E12: =구매리스트!I4 -> 0 | H12: 모델연도 | K12: =구매리스트!D6 -> 0
C13: Type of Engine | H13: Model Year
C14: 제원관리번호 | E14: =구매리스트!G5 -> 0 | H14: 용도 Vehicle Use | K14: =구매리스트!B8 -> 0
C15: Specification
C16: Management no.
C17: 최초등록일 | E17: =구매리스트!B6 -> 0 | H17: 사업용사용기간
C18: Dete of initial | H18: Period of
C19: Registraton | H19: Business Usage
A21: 소유자 | C21: 성명 (명칭) | E21: 주식회사싼카 | H21: 생년월일(법인등록번호) | K21: 120111-0922270
A22: Owner | C22: Name | H22: Date of birth (Corporate Registration No.)
A24: 말소등록일 | E24: =구매리스트!B7 -> 0 | H24: 증명서 용도 | K24: 증명용
A25: Date of De-reglstration | H25: Use of Certificate
A26: 말소등록구분 | E26: 수출예정(수출말소) | H26: 권리관계여부 | K26: 압류(Seiure) | M26: : | N26: 0 | O26: 건
A27: Reason for De-registration | H27: Relation of Rights | K27: 저당권(Mortgage) | M27: : | N27: 0 | O27: 건
A29: 「자동차관리법」제13조 및 「자동차등록규칙」제40조에 따라 말소등록 되었음을 증명합니다.
A30: This is to certify that the above vehicle was de-registered in accordance with Article 13 of the Motor
A31: Vehicle Management Act and Article 40 of the Motor Vehicle Registration Rules.
G33: 발행 연월일 Date of Issue : | K33: =E24 -> 0
G34: 대 한 민 국
A35: Speial Metropolitan City Mayor ' Metropolitan City Mayor'
A36: Special Self-Governing City Mayor ' Do Governor ' Special Self-Governign Province Governor
A37: (The Head of a Si / Gun / Gu
A38: 유의사항
A39: 1. 말소등록된 자동차를 다시 등록하여 사용하려는 경우에는 「자동차등록령」 제20조 및 아래 표의 구분에 따른 기간에 신규등록을 신청해야 하며,그
A40: 신청기간을 경과한 때에는 「자동차관리법」제84조제4항제7호에 따라 100만원 이하의 과태료를 납부해야 합니다.
A41: 2. 말소등록 당시에 압류 및 저당권 등이 등록된 자동차는 「자동차관리법」제13조제10항 후단에 따라 해당 관리관계가 소멸되었음을 「자동차등록규칙」
A42: 제27조제3항에 따라 증명한 경우에만 신규등록을 신청할 수 있습니다.
A43: 말소등록 사유 | K43: 신규등록 신청 기간
A44: 1.「여객자동차 운수사업법」및 「화물자동차 운사사업법」에 따라 면허.등록.인가 또는 신고가 실효되거나 취소되어 | K44: 말소등록일부터 3개월 이내
A45: 말소들록된 경우
...

Sheet 차량인보이스
A1: COMMERCIAL INVOICE
A2: 1) Shipper / Exporter | E2: Reference No. DFSU6646075 | G2: =구매리스트!B12 -> 0 | H2: ORIGINAL
A3: SSANCAR LTD., 163 Sangidaehak-ro, Siheung-si, Gyeonggi-do, Republic of Korea TEL:82-505-355-9977 FAX:82-505-366-9977 EMAIL : ssancar9977@gmail.com | E3: Reference code. DFSU6646075 | G3: =구매리스트!B12 -> 0
E4: CERTIFICATE OF ORIGIN
E6: Issued by
E7: THE KOREA CHAMBER OF COMMERCE & INDUSTRY
A8: 2) For account & risk of Messers. | E8: Seoul, Republic of korea
A9: =구매리스트!B14 -> 0 | E9: *Remark
E10: 8) No. & date of invoice
E11: =구매리스트!B3 -> 0 | I11: =TODAY() -> 0
A12: 3) Notify party | E12: 9) No. & date of L/C
A13: SAME AS ABOVE | E13: TTR BASE
A15: 4) Port of loading | C15: 5) Final Destination | E15: 10) L/C issuing bank
A16: =구매리스트!B10 -> 0 | C16: =구매리스트!D10 -> 0
A17: 6) Vessel name | C17: 7) Sailing on or about | E17: =구매리스트!D12 -> 0
A18: =구매리스트!B11 -> 0 | C18: =구매리스트!D11 -> 0
A19: 11) MARKS AND NUMBERS OF PKGS | C19: 12) Description of Goods | E19: 13) Quantity | G19: 14) Unit price | H19: 15) Amount | I19: 16) DISPLACE-MENT(cc)
A21: NO. | B21: Commodity | C21: Year | D21: Chassis No. | E21: Q'TY | G21: Unit Price | H21: AMOUNT | I21: Shipping
A22: 1 | B22: =구매리스트!B5 -> 0 | C22: =구매리스트!D6 -> 0 | D22: =구매리스트!D5 -> 0 | E22: 1 | G22: =구매리스트!B15 -> 0 | H22: =SUM(G22) -> 0 | I22: =구매리스트!D15 -> 0 | J22: =SUM(H22:I22) -> 0
A24: 2 | J24: 0
A26: 3 | J26: 0
A28: 4 | J28: 0
A30: 5
D32: GRAND TOTAL : | H32: =SUM(H22:I22,H24:I24,H26:I26,H28:I28,H30:I30) -> 0
A34: Telephone No : 82- 10 - 9009 - 9977 | E34: Signed By
A35: Fax No : 82- 505 - 366 - 9977

Sheet 차량팩킹
A1: COMMERCIAL PACKING LIST
A2: 1) Shipper / Exporter | E2: Reference No. DFSU6646075 | G2: =차량인보이스!G2 -> 0 | H2: ORIGINAL
A3: SSANCAR LTD., 163 Sangidaehak-ro, Siheung-si, Gyeonggi-do, Republic of Korea TEL:82-505-355-9977 FAX:82-505-366-9977 EMAIL : ssancar9977@gmail.com | E3: Reference code. DFSU6646075 | G3: =차량인보이스!G3 -> 0
E4: CERTIFICATE OF ORIGIN
E6: Issued by
E7: THE KOREA CHAMBER OF COMMERCE & INDUSTRY
A8: 2) For account & risk of Messers. | E8: Seoul, Republic of korea
A9: =차량인보이스!A9 -> 0 | E9: *Remark
E10: 8) No. & date of invoice
E11: =구매리스트!B3 -> 0 | I11: =TODAY() -> 0
A12: 3) Notify party | E12: 9) No. & date of L/C
A13: SAME AS ABOVE | E13: TTR BASE
A15: 4) Port of loading | C15: 5) Final Destination | E15: 10) L/C issuing bank
A16: =구매리스트!B10 -> 0 | C16: =구매리스트!D10 -> 0
A17: 6) Vessel name | C17: 7) Sailing on or about | E17: =차량인보이스!E17 -> 0
A18: =구매리스트!B11 -> 0 | C18: =구매리스트!D11 -> 0
A19: 11) MARKS AND NUMBERS OF PKGS | C19: 12) Description of Goods | E19: 13) Quantity | G19: 14) Unit price | H19: 15) Amount | I19: 16) WEIGHT
A21: NO. | B21: Commodity | C21: Year | D21: Chassis No. | E21: Q'TY | G21: Unit Price | H21: AMOUNT | I21: Weight (KG)
A22: 1 | B22: =차량인보이스!B22 -> 0 | C22: =구매리스트!D6 -> 0 | D22: =차량인보이스!D22 -> 0 | E22: =차량인보이스!E22 -> 0 | I22: =구매리스트!I8 -> 0
A24: 2
A26: 3
A28: 4
A30: 5
D32: GRAND TOTAL : | H32: =SUM(I22,I24,I26,I28,I30) -> 0
A34: Telephone No : 82- 10 - 9009 - 9977 | E34: Signed By
A35: Fax No : 82- 505 - 366 - 9977

Sheet Travel Services Invoice
E1: PROFORMA INVOICE
A2: Ssancar LTD 163 Sangidaehak-ro, Siheung-si, Gyeonggi-do, Korea Phone: +82-505-355-9977
E3: Date | F3: =구매리스트!D11 -> 0
E4: Invoice No. | F4: =구매리스트!B3 -> 0
E5: Name | F5: =구매리스트!D14 -> 0
E6: Nit
E7: Address
E8: Country
E9: Phone
E11: Total invoice | F11: =F31 -> 0
E12: Total received in Korea | F12: =F31 -> 0
E13: Not received | F13: =SUM(F11-F12) -> 0
A15: BANK ACCOUNT INFORMATION
A16: Beneficiary | C16: SSANCAR CO LTD | E16: Bank Name | F16: SHINHAN BANK
A17: Swift Code | C17: SHBKKRSE | E17: Bank Address | F17: 20,Sejong-Daero9-Gil,Jung-Gu Seoul South Korea
A18: Bank Account Number | C18: 180-008-400167 | E18: Beneficiary Address | F18: 163 Sangidaehak-ro, Siheung-si, Gyeonggi-do, SOUTH KOREA
A20: Code | B20: Model | C20: Chassis Number | D20: Year | E20: Lot. No. | F20: Total
A21: =구매리스트!B3 -> 0 | B21: =구매리스트!B5 -> 0 | C21: =구매리스트!D5 -> 0 | D21: =구매리스트!D6 -> 0 | F21: =차량인보이스!H22 -> 0
E28: Sub Total | F28: =SUM(F21:G27) -> 0
E29: Shipping Cost | F29: =차량인보이스!I22 -> 0
E31: Grend Total | F31: =SUM(F28:G29) -> 0
